<mujoco model="ant">
	<custom>
		<numeric data="0.0 0.0 0.55 1.0 0.0 0.0 0.0 0.0 1.0 0.0 -1.0 0.0 -1.0 0.0 1.0" name="init_qpos"/>
	</custom>

	<default>
		<joint armature="0.01" damping="0.1" limited="true"/>
		<geom condim="3" density="5.0" friction="1.5 0.1 0.1" margin="0.01" rgba="0.97 0.38 0.06 1"/>
	</default>

	<compiler inertiafromgeom="true" angle="degree"/>

	<option timestep="0.016" iterations="50" tolerance="1e-10" solver="Newton" jacobian="dense" cone="pyramidal"/>

	<size nconmax="50" njmax="200" nstack="10000"/>
	<visual>
			<map force="0.1" zfar="30"/>
			<rgba haze="0.15 0.25 0.35 1"/>
			<quality shadowsize="2048"/>
			<global offwidth="800" offheight="800"/>
	</visual>

	<asset>
			<texture type="skybox" builtin="gradient" rgb1="0.3 0.5 0.7" rgb2="0 0 0" width="512" height="512"/> 
			<texture name="texplane" type="2d" builtin="checker" rgb1=".2 .3 .4" rgb2=".1 0.15 0.2" width="512" height="512" mark="cross" markrgb=".8 .8 .8"/>
			<texture name="texgeom" type="cube" builtin="flat" mark="cross" width="127" height="1278" 
					rgb1="0.8 0.6 0.4" rgb2="0.8 0.6 0.4" markrgb="1 1 1" random="0.01"/>	
	
			<material name="matplane" reflectance="0.3" texture="texplane" texrepeat="1 1" texuniform="true"/>
			<material name="matgeom" texture="texgeom" texuniform="true" rgba="0.8 0.6 .4 1"/>
	</asset>

	<worldbody>
		<geom name="floor" pos="0 0 0" size="0 0 .25" type="plane" material="matplane" condim="3"/>

		<light directional="false" diffuse=".2 .2 .2" specular="0 0 0" pos="0 0 5" dir="0 0 -1" castshadow="false"/>
		<light mode="targetbodycom" target="torso" directional="false" diffuse=".8 .8 .8" specular="0.3 0.3 0.3" pos="0 0 4.0" dir="0 0 -1"/>

		<body name="torso" pos="0 0 0.75" friction="1 0.005 0.0001">
			<freejoint name="root"/>
			<geom name="torso_geom" pos="0 0 0" size="0.1 0.1 0.1" type="box"/>
			<body name="front_leg" pos="0.15 0 0">
				<joint axis="0 0 1" name="hip_1" pos="0.0 0.0 0.0" range="0 0" type="hinge"/>
				<!-- <joint axis="0 0 1" name="hip_1" pos="0.0 0.0 0.0" range="0 0" type="fixed"/> -->
				<geom fromto="-0.05 0.0 0.0 0.05 0 0.0" name="left_leg_geom" size="0.02" type="capsule" rgba=".999 .2 .1 1"/>
			</body>
			<body name="back_leg" pos="-0.15 0 0">
				<joint axis="0 0 1" name="hip_1" pos="0.0 0.0 0.0" range="0 0" type="hinge"/>
				<!-- <joint axis="0 0 1" name="hip_1" pos="0.0 0.0 0.0" range="0 0" type="fixed"/> -->
				<geom fromto="-0.05 0.0 0.0 0.05 0 0.0" name="left_leg_geom" size="0.02" type="capsule" rgba=".999 .2 .1 1"/>
			</body>
		</body>
	</worldbody>
	
</mujoco>
