<?xml version="1.0" ?>
<robot name="partnet_59d99d0a2b385fe81b1a00a31bfed97b">
	<link name="base"/>
	<link name="link_0">
		<visual name="handle-1">
			<origin xyz="0 -0.48305199267419374 -0.02847403130494055"/>
			<geometry>
				<mesh filename="textured_objs/original-7.obj"  scale="0.1 0.1 0.1"/>
			</geometry>
		</visual>
		<collision>
			<origin xyz="0 -0.48305199267419374 -0.02847403130494055"/>
			<geometry>
				<mesh filename="textured_objs/original-7.obj"  scale="0.1 0.1 0.1"/>
			</geometry>
		</collision>
	</link>
	<joint name="joint_0" type="revolute">
		<origin xyz="0 0.48305199267419374 0.02847403130494055"/>
		<axis xyz="-1 0 0"/>
		<child link="link_0"/>
		<parent link="link_1"/>
		<limit lower="-2.249380339970292" upper="1.985486557068749"/>
	</joint>
	<link name="link_1">
		<visual name="base_body-2">
			<origin xyz="0 0 0"/>
			<geometry>
				<mesh filename="textured_objs/original-4.obj"  scale="0.1 0.1 0.1"/>
			</geometry>
		</visual>
		<visual name="base_body-2">
			<origin xyz="0 0 0"/>
			<geometry>
				<mesh filename="textured_objs/original-3.obj"  scale="0.1 0.1 0.1"/>
			</geometry>
		</visual>
		<visual name="base_body-2">
			<origin xyz="0 0 0"/>
			<geometry>
				<mesh filename="textured_objs/original-2.obj"  scale="0.1 0.1 0.1"/>
			</geometry>
		</visual>
		<visual name="base_body-2">
			<origin xyz="0 0 0"/>
			<geometry>
				<mesh filename="textured_objs/original-8.obj"  scale="0.1 0.1 0.1"/>
			</geometry>
		</visual>
		<visual name="base_body-2">
			<origin xyz="0 0 0"/>
			<geometry>
				<mesh filename="textured_objs/original-13.obj"  scale="0.1 0.1 0.1"/>
			</geometry>
		</visual>
		<visual name="base_body-2">
			<origin xyz="0 0 0"/>
			<geometry>
				<mesh filename="textured_objs/original-5.obj"  scale="0.1 0.1 0.1"/>
			</geometry>
		</visual>
		<visual name="base_body-2">
			<origin xyz="0 0 0"/>
			<geometry>
				<mesh filename="textured_objs/original-6.obj"  scale="0.1 0.1 0.1"/>
			</geometry>
		</visual>
		<visual name="base_body-2">
			<origin xyz="0 0 0"/>
			<geometry>
				<mesh filename="textured_objs/original-11.obj"  scale="0.1 0.1 0.1"/>
			</geometry>
		</visual>
		<visual name="base_body-2">
			<origin xyz="0 0 0"/>
			<geometry>
				<mesh filename="textured_objs/original-1.obj"  scale="0.1 0.1 0.1"/>
			</geometry>
		</visual>
		<visual name="base_body-2">
			<origin xyz="0 0 0"/>
			<geometry>
				<mesh filename="textured_objs/original-10.obj"  scale="0.1 0.1 0.1"/>
			</geometry>
		</visual>
		<visual name="base_body-2">
			<origin xyz="0 0 0"/>
			<geometry>
				<mesh filename="textured_objs/original-14.obj"  scale="0.1 0.1 0.1"/>
			</geometry>
		</visual>
		<collision>
			<origin xyz="0 0 0"/>
			<geometry>
				<mesh filename="textured_objs/original-4.obj"  scale="0.1 0.1 0.1"/>
			</geometry>
		</collision>
		<collision>
			<origin xyz="0 0 0"/>
			<geometry>
				<mesh filename="textured_objs/original-3.obj"  scale="0.1 0.1 0.1"/>
			</geometry>
		</collision>
		<collision>
			<origin xyz="0 0 0"/>
			<geometry>
				<mesh filename="textured_objs/original-2.obj"  scale="0.1 0.1 0.1"/>
			</geometry>
		</collision>
		<collision>
			<origin xyz="0 0 0"/>
			<geometry>
				<mesh filename="textured_objs/original-8.obj"  scale="0.1 0.1 0.1"/>
			</geometry>
		</collision>
		<collision>
			<origin xyz="0 0 0"/>
			<geometry>
				<mesh filename="textured_objs/original-13.obj"  scale="0.1 0.1 0.1"/>
			</geometry>
		</collision>
		<collision>
			<origin xyz="0 0 0"/>
			<geometry>
				<mesh filename="textured_objs/original-5.obj"  scale="0.1 0.1 0.1"/>
			</geometry>
		</collision>
		<collision>
			<origin xyz="0 0 0"/>
			<geometry>
				<mesh filename="textured_objs/original-6.obj"  scale="0.1 0.1 0.1"/>
			</geometry>
		</collision>
		<collision>
			<origin xyz="0 0 0"/>
			<geometry>
				<mesh filename="textured_objs/original-11.obj"  scale="0.1 0.1 0.1"/>
			</geometry>
		</collision>
		<collision>
			<origin xyz="0 0 0"/>
			<geometry>
				<mesh filename="textured_objs/original-1.obj"  scale="0.1 0.1 0.1"/>
			</geometry>
		</collision>
		<collision>
			<origin xyz="0 0 0"/>
			<geometry>
				<mesh filename="textured_objs/original-10.obj"  scale="0.1 0.1 0.1"/>
			</geometry>
		</collision>
		<collision>
			<origin xyz="0 0 0"/>
			<geometry>
				<mesh filename="textured_objs/original-14.obj"  scale="0.1 0.1 0.1"/>
			</geometry>
		</collision>
	</link>
	<joint name="joint_1" type="fixed">
		<origin rpy="1.570796326794897 0 -1.570796326794897" xyz="0 0 0"/>
		<child link="link_1"/>
		<parent link="base"/>
	</joint>
</robot>
