<!-- See LICENSE.md for legal notices. LICENSE.md must be kept together with this file. -->
<mujoco>
    <body name="robot1:hand mount" pos="1 1.25 0.15" euler="1.5708 0 3.14159">
        <inertial mass="0.1" pos="0 0 0" diaginertia="0.001 0.001 0.001"></inertial>
        <body childclass="robot1:asset_class" name="robot1:forearm" pos="0 0.01 0" euler="0 0 0">
            <inertial pos="0.001 -0.002 0.29" quat="0.982 -0.016 0 -0.188" mass="4" diaginertia="0.01 0.01 0.0075"></inertial>
            <geom class="robot1:D_Vizual" pos="0 0.01 0.04" name="robot1:V_forearm" mesh="robot1:forearm" euler="0 0 1.57"></geom>
            <geom class="robot1:DC_Hand" name="robot1:C_forearm" type="mesh" mesh="robot1:forearm_cvx" pos="0 0.01 0.04" euler="0 0 1.57" rgba="0.4 0.5 0.6 0.7"></geom>
            <body name="robot1:wrist" pos="0 0 0.256">
                <inertial pos="0.003 0 0.016" quat="0.504 0.496 0.495 0.504" mass="0.3" diaginertia="0.001 0.001 0.001"></inertial>
                <joint name="robot1:WRJ1" type="hinge" pos="0 0 0" axis="0 1 0" range="-0.489 0.14" damping="0.5" armature="0.005" user="1123"></joint>
                <geom class="robot1:D_Vizual" name="robot1:V_wrist" mesh="robot1:wrist"></geom>
                <geom class="robot1:DC_Hand" name="robot1:C_wrist" type="capsule" pos="0 0 0" quat="0.707 0.707 0 0" size="0.015 0.01" rgba="0.4 0.5 0.6 0.1"></geom>
                <body name="robot1:palm" pos="0 0 0.034">
                    <inertial pos="0.006 0 0.036" quat="0.716 0.044 0.075 0.693" mass="0.3" diaginertia="0.001 0.001 0.001"></inertial>
                    <joint name="robot1:WRJ0" type="hinge" pos="0 0 0" axis="1 0 0" range="-0.698 0.489" damping="0.5" armature="0.005" user="1122"></joint>
                    <geom class="robot1:D_Vizual" name="robot1:V_palm" mesh="robot1:palm"></geom>
                    <geom class="robot1:DC_Hand" name="robot1:C_palm0" type="box" pos="0.011 0 0.038" size="0.032 0.0111 0.049" rgba="0.4 0.5 0.6 0.1"></geom>
                    <geom class="robot1:DC_Hand" name="robot1:C_palm1" type="box" pos="-0.032 0 0.014" size="0.011 0.0111 0.025" rgba="0.4 0.5 0.6 0.1"></geom>
                    <body name="robot1:ffknuckle" pos="0.033 0 0.095">
                        <inertial pos="0 0 0" quat="0.52 0.854 0.006 -0.003" mass="0.008" diaginertia="1e-05 1e-05 1e-05"></inertial>
                        <joint name="robot1:FFJ3" type="hinge" pos="0 0 0" axis="0 1 0" range="-0.349 0.349" user="1103"></joint>
                        <geom class="robot1:D_Vizual" name="robot1:V_ffknuckle" mesh="robot1:knuckle"></geom>
                        <body name="robot1:ffproximal" pos="0 0 0">
                            <inertial pos="0 0 0.023" quat="0.707 -0.004 0.004 0.707" mass="0.014" diaginertia="1e-05 1e-05 1e-05"></inertial>
                            <joint name="robot1:FFJ2" type="hinge" pos="0 0 0" axis="1 0 0" range="0 1.571" user="1102"></joint>
                            <geom class="robot1:D_Vizual" name="robot1:V_ffproximal" mesh="robot1:F3"></geom>
                            <geom class="robot1:DC_Hand" name="robot1:C_ffproximal" type="capsule" pos="0 0 0.0225" size="0.01 0.0225"></geom>
                            <body name="robot1:ffmiddle" pos="0 0 0.045">
                                <inertial pos="0 0 0.011" quat="0.707 0 0 0.707" mass="0.012" diaginertia="1e-05 1e-05 1e-05"></inertial>
                                <joint name="robot1:FFJ1" type="hinge" pos="0 0 0" axis="1 0 0" range="0 1.571" user="1101"></joint>
                                <geom class="robot1:D_Vizual" name="robot1:V_ffmiddle" mesh="robot1:F2"></geom>
                                <geom class="robot1:DC_Hand" name="robot1:C_ffmiddle" type="capsule" pos="0 0 0.0125" size="0.00805 0.0125"></geom>
                                <body name="robot1:ffdistal" pos="0 0 0.025">
                                    <inertial pos="0 0 0.015" quat="0.707 -0.003 0.003 0.707" mass="0.01" diaginertia="1e-05 1e-05 1e-05"></inertial>
                                    <joint name="robot1:FFJ0" type="hinge" pos="0 0 0" axis="1 0 0" range="0 1.571" user="1100"></joint>
                                    <geom class="robot1:D_Vizual" name="robot1:V_ffdistal" pos="0 0 0.001" mesh="robot1:F1"></geom>
                                    <geom class="robot1:DC_Hand" name="robot1:C_ffdistal" type="capsule" pos="0 0 0.012" size="0.00705 0.012" condim="4"></geom>
                                    <site name="robot1:S_fftip" pos="0 0 0.026" group="3"></site>
                                    <site class="robot1:D_Touch" name="robot1:Tch_fftip"></site>
                                </body>
                            </body>
                        </body>
                    </body>
                    <body name="robot1:mfknuckle" pos="0.011 0 0.099">
                        <inertial pos="0 0 0" quat="0.52 0.854 0.006 -0.003" mass="0.008" diaginertia="1e-05 1e-05 1e-05"></inertial>
                        <joint name="robot1:MFJ3" type="hinge" pos="0 0 0" axis="0 1 0" range="-0.349 0.349" user="1107"></joint>
                        <geom class="robot1:D_Vizual" name="robot1:V_mfknuckle" mesh="robot1:knuckle"></geom>
                        <body name="robot1:mfproximal" pos="0 0 0">
                            <inertial pos="0 0 0.023" quat="0.707 -0.004 0.004 0.707" mass="0.014" diaginertia="1e-05 1e-05 1e-05"></inertial>
                            <joint name="robot1:MFJ2" type="hinge" pos="0 0 0" axis="1 0 0" range="0 1.571" user="1106"></joint>
                            <geom class="robot1:D_Vizual" name="robot1:V_mfproximal" mesh="robot1:F3"></geom>
                            <geom class="robot1:DC_Hand" name="robot1:C_mfproximal" type="capsule" pos="0 0 0.0225" size="0.01 0.0225"></geom>
                            <body name="robot1:mfmiddle" pos="0 0 0.045">
                                <inertial pos="0 0 0.012" quat="0.707 0 0 0.707" mass="0.012" diaginertia="1e-05 1e-05 1e-05"></inertial>
                                <joint name="robot1:MFJ1" type="hinge" pos="0 0 0" axis="1 0 0" range="0 1.571" user="1105"></joint>
                                <geom class="robot1:D_Vizual" name="robot1:V_mfmiddle" mesh="robot1:F2"></geom>
                                <geom class="robot1:DC_Hand" name="robot1:C_mfmiddle" type="capsule" pos="0 0 0.0125" size="0.00805 0.0125"></geom>
                                <body name="robot1:mfdistal" pos="0 0 0.025">
                                    <inertial pos="0 0 0.015" quat="0.707 -0.003 0.003 0.707" mass="0.01" diaginertia="1e-05 1e-05 1e-05"></inertial>
                                    <joint name="robot1:MFJ0" type="hinge" pos="0 0 0" axis="1 0 0" range="0 1.571" user="1104"></joint>
                                    <geom class="robot1:D_Vizual" name="robot1:V_mfdistal" mesh="robot1:F1"></geom>
                                    <geom class="robot1:DC_Hand" name="robot1:C_mfdistal" type="capsule" pos="0 0 0.012" size="0.00705 0.012" condim="4"></geom>
                                    <site name="robot1:S_mftip" pos="0 0 0.026" group="3"></site>
                                    <site class="robot1:D_Touch" name="robot1:Tch_mftip"></site>
                                </body>
                            </body>
                        </body>
                    </body>
                    <body name="robot1:rfknuckle" pos="-0.011 0 0.095">
                        <inertial pos="0 0 0" quat="0.52 0.854 0.006 -0.003" mass="0.008" diaginertia="1e-05 1e-05 1e-05"></inertial>
                        <joint name="robot1:RFJ3" type="hinge" pos="0 0 0" axis="0 1 0" range="-0.349 0.349" user="1111"></joint>
                        <geom class="robot1:D_Vizual" name="robot1:V_rfknuckle" mesh="robot1:knuckle"></geom>
                        <body name="robot1:rfproximal" pos="0 0 0">
                            <inertial pos="0 0 0.023" quat="0.707 -0.004 0.004 0.707" mass="0.014" diaginertia="1e-05 1e-05 1e-05"></inertial>
                            <joint name="robot1:RFJ2" type="hinge" pos="0 0 0" axis="1 0 0" range="0 1.571" user="1110"></joint>
                            <geom class="robot1:D_Vizual" name="robot1:V_rfproximal" mesh="robot1:F3"></geom>
                            <geom class="robot1:DC_Hand" name="robot1:C_rfproximal" type="capsule" pos="0 0 0.0225" size="0.01 0.0225"></geom>
                            <body name="robot1:rfmiddle" pos="0 0 0.045">
                                <inertial pos="0 0 0.012" quat="0.707 0 0 0.707" mass="0.012" diaginertia="1e-05 1e-05 1e-05"></inertial>
                                <joint name="robot1:RFJ1" type="hinge" pos="0 0 0" axis="1 0 0" range="0 1.571" user="1109"></joint>
                                <geom class="robot1:D_Vizual" name="robot1:V_rfmiddle" mesh="robot1:F2"></geom>
                                <geom class="robot1:DC_Hand" name="robot1:C_rfmiddle" type="capsule" pos="0 0 0.0125" size="0.00805 0.0125"></geom>
                                <body name="robot1:rfdistal" pos="0 0 0.025">
                                    <inertial pos="0 0 0.015" quat="0.707 -0.003 0.003 0.707" mass="0.01" diaginertia="1e-05 1e-05 1e-05"></inertial>
                                    <joint name="robot1:RFJ0" type="hinge" pos="0 0 0" axis="1 0 0" range="0 1.571" user="1108"></joint>
                                    <geom class="robot1:D_Vizual" name="robot1:V_rfdistal" mesh="robot1:F1" pos="0 0 0.001"></geom>
                                    <geom class="robot1:DC_Hand" name="robot1:C_rfdistal" type="capsule" pos="0 0 0.012" size="0.00705 0.012" condim="4"></geom>
                                    <site name="robot1:S_rftip" pos="0 0 0.026" group="3"></site>
                                    <site class="robot1:D_Touch" name="robot1:Tch_rftip"></site>
                                </body>
                            </body>
                        </body>
                    </body>
                    <body name="robot1:lfmetacarpal" pos="-0.017 0 0.044">
                        <inertial pos="-0.014 0.001 0.014" quat="0.709 -0.092 -0.063 0.696" mass="0.075" diaginertia="1e-05 1e-05 1e-05"></inertial>
                        <joint name="robot1:LFJ4" type="hinge" pos="0 0 0" axis="0.571 0 0.821" range="0 0.785" user="1116"></joint>
                        <geom class="robot1:D_Vizual" name="robot1:V_lfmetacarpal" pos="-0.016 0 -0.023" mesh="robot1:lfmetacarpal"></geom>
                        <geom class="robot1:DC_Hand" name="robot1:C_lfmetacarpal" type="box" pos="-0.0165 0 0.01" size="0.0095 0.0111 0.025" rgba="0.4 0.5 0.6 0.2"></geom>
                        <body name="robot1:lfknuckle" pos="-0.017 0 0.044">
                            <inertial pos="0 0 0" quat="0.52 0.854 0.006 -0.003" mass="0.008" diaginertia="1e-05 1e-05 1e-05"></inertial>
                            <joint name="robot1:LFJ3" type="hinge" pos="0 0 0" axis="0 1 0" range="-0.349 0.349" user="1115"></joint>
                            <geom class="robot1:D_Vizual" name="robot1:V_lfknuckle" mesh="robot1:knuckle"></geom>
                            <body name="robot1:lfproximal" pos="0 0 0">
                                <inertial pos="0 0 0.023" quat="0.707 -0.004 0.004 0.707" mass="0.014" diaginertia="1e-05 1e-05 1e-05"></inertial>
                                <joint name="robot1:LFJ2" type="hinge" pos="0 0 0" axis="1 0 0" range="0 1.571" user="1114"></joint>
                                <geom class="robot1:D_Vizual" name="robot1:V_lfproximal" mesh="robot1:F3"></geom>
                                <geom class="robot1:DC_Hand" name="robot1:C_lfproximal" type="capsule" pos="0 0 0.0225" size="0.01 0.0225"></geom>
                                <body name="robot1:lfmiddle" pos="0 0 0.045">
                                    <inertial pos="0 0 0.012" quat="0.707 0 0 0.707" mass="0.012" diaginertia="1e-05 1e-05 1e-05"></inertial>
                                    <joint name="robot1:LFJ1" type="hinge" pos="0 0 0" axis="1 0 0" range="0 1.571" user="1113"></joint>
                                    <geom class="robot1:D_Vizual" name="robot1:V_lfmiddle" mesh="robot1:F2"></geom>
                                    <geom class="robot1:DC_Hand" name="robot1:C_lfmiddle" type="capsule" pos="0 0 0.0125" size="0.00805 0.0125"></geom>
                                    <body name="robot1:lfdistal" pos="0 0 0.025">
                                        <inertial pos="0 0 0.015" quat="0.707 -0.003 0.003 0.707" mass="0.01" diaginertia="1e-05 1e-05 1e-05"></inertial>
                                        <joint name="robot1:LFJ0" type="hinge" pos="0 0 0" axis="1 0 0" range="0 1.571" user="1112"></joint>
                                        <geom class="robot1:D_Vizual" name="robot1:V_lfdistal" mesh="robot1:F1" pos="0 0 0.001"></geom>
                                        <geom class="robot1:DC_Hand" name="robot1:C_lfdistal" type="capsule" pos="0 0 0.012" size="0.00705 0.012" condim="4"></geom>
                                        <site name="robot1:S_lftip" pos="0 0 0.026" group="3"></site>
                                        <site class="robot1:D_Touch" name="robot1:Tch_lftip"></site>
                                    </body>
                                </body>
                            </body>
                        </body>
                    </body>
                    <body name="robot1:thbase" pos="0.034 -0.009 0.029" axisangle="0 1 0 0.785">
                        <inertial pos="0 0 0" mass="0.01" diaginertia="1e-05 1e-05 1e-05"></inertial>
                        <joint name="robot1:THJ4" type="hinge" pos="0 0 0" axis="0 0 -1" range="-1.047 1.047" user="1121"></joint>
                        <geom name="robot1:V_thbase" type="box" group="1" pos="0 0 0" size="0.001 0.001 0.001"></geom>
                        <body name="robot1:thproximal" pos="0 0 0">
                            <inertial pos="0 0 0.017" quat="0.982 0 0.001 0.191" mass="0.016" diaginertia="1e-05 1e-05 1e-05"></inertial>
                            <joint name="robot1:THJ3" type="hinge" pos="0 0 0" axis="1 0 0" range="0 1.222" user="1120"></joint>
                            <geom class="robot1:D_Vizual" name="robot1:V_thproximal" mesh="robot1:TH3_z"></geom>
                            <geom class="robot1:DC_Hand" name="robot1:C_thproximal" type="capsule" pos="0 0 0.019" size="0.013 0.019" rgba="0.4 0.5 0.6 0.1"></geom>
                            <body name="robot1:thhub" pos="0 0 0.038">
                                <inertial pos="0 0 0" mass="0.002" diaginertia="1e-05 1e-05 1e-05"></inertial>
                                <joint name="robot1:THJ2" type="hinge" pos="0 0 0" axis="1 0 0" range="-0.209 0.209" user="1119"></joint>
                                <geom name="robot1:V_thhub" type="box" group="1" pos="0 0 0" size="0.001 0.001 0.001"></geom>
                                <body name="robot1:thmiddle" pos="0 0 0">
                                    <inertial pos="0 0 0.016" quat="1 -0.001 -0.007 0.003" mass="0.016" diaginertia="1e-05 1e-05 1e-05"></inertial>
                                    <joint name="robot1:THJ1" type="hinge" pos="0 0 0" axis="0 1 0" range="-0.524 0.524" user="1118"></joint>
                                    <geom class="robot1:D_Vizual" name="robot1:V_thmiddle" mesh="robot1:TH2_z"></geom>
                                    <geom class="robot1:DC_Hand" name="robot1:C_thmiddle" type="capsule" pos="0 0 0.016" size="0.011 0.016"></geom>
                                    <body name="robot1:thdistal" pos="0 0 0.032">
                                        <inertial pos="0 0 0.016" quat="0.999 -0.005 -0.047 0.005" mass="0.016" diaginertia="1e-05 1e-05 1e-05"></inertial>
                                        <joint name="robot1:THJ0" type="hinge" pos="0 0 0" axis="0 1 0" range="-1.571 0" user="1117"></joint>
                                        <geom class="robot1:D_Vizual" name="robot1:V_thdistal" mesh="robot1:TH1_z"></geom>
                                        <geom class="robot1:DC_Hand" name="robot1:C_thdistal" type="capsule" pos="0 0 0.013" size="0.00918 0.013" condim="4"></geom>
                                        <site name="robot1:S_thtip" pos="0 0 0.0275" group="3"></site>
                                        <site class="robot1:D_Touch" name="robot1:Tch_thtip" size="0.005 0.011 0.016" pos="-0.005 0 0.02"></site>
                                    </body>
                                </body>
                            </body>
                        </body>
                    </body>
                </body>
            </body>
        </body>
    </body>
</mujoco>
